<?xml version="1.0" ?>
<!-- =================================================================================== -->
<!-- |    This document was autogenerated by xacro from /home/duser/clearpath/robot.urdf.xacro | -->
<!-- |    EDITING THIS FILE BY HAND IS NOT RECOMMENDED                                 | -->
<!-- =================================================================================== -->
<robot name="w200-0000">
  <material name="clearpath_dark_grey">
    <color rgba="0.2 0.2 0.2 1.0"/>
  </material>
  <material name="clearpath_medium_grey">
    <color rgba="0.6 0.6 0.6 1.0"/>
  </material>
  <material name="clearpath_light_grey">
    <color rgba="0.8 0.8 0.8 1.0"/>
  </material>
  <material name="clearpath_yellow">
    <color rgba="0.8 0.8 0.0 1.0"/>
  </material>
  <material name="clearpath_black">
    <color rgba="0.15 0.15 0.15 1.0"/>
  </material>
  <material name="clearpath_white">
    <color rgba="1.0 1.0 1.0 1.0"/>
  </material>
  <material name="clearpath_red">
    <color rgba="1.0 0.0 0.0 1.0"/>
  </material>
  <material name="clearpath_aluminum">
    <color rgba="0.5 0.5 0.5 1"/>
  </material>
  <material name="clearpath_plastic">
    <color rgba="0.1 0.1 0.1   1"/>
  </material>
  <material name="warthog_yellow">
    <color rgba="0.95 0.816 0.082 1.0"/>
  </material>
  <material name="warthog_orange">
    <color rgba="1.0 0.48 0.0 1.0"/>
  </material>
  <material name="warthog_olive">
    <color rgba="0.333 0.419 0.184 1.0"/>
  </material>
  <material name="warthog_sand">
    <color rgba="0.86 0.75 0.54 1.0"/>
  </material>
  <!-- Chassis -->
  <link name="base_link"/>
  <joint name="base_link_joint" type="fixed">
    <origin rpy="0 0 0" xyz="0 0 0.025"/>
    <parent link="base_link"/>
    <child link="chassis_link"/>
  </joint>
  <link name="chassis_link">
    <inertial>
      <origin rpy="0 0 0" xyz="0 0 0"/>
      <mass value="100"/>
      <inertia ixx="4.833333333333333" ixy="0" ixz="0" iyy="15.937500000000002" iyz="0" izz="15.937500000000002"/>
    </inertial>
    <visual>
      <origin rpy="0 0 0" xyz="0 0 0"/>
      <geometry>
        <mesh filename="package://clearpath_platform_description/meshes/w200/chassis.stl"/>
      </geometry>
      <material name="clearpath_black">
        <color rgba="0.15 0.15 0.15 1.0"/>
      </material>
    </visual>
    <visual>
      <origin rpy="0 0 0" xyz="0 0 0"/>
      <geometry>
        <mesh filename="package://clearpath_platform_description/meshes/w200/e-stop.stl"/>
      </geometry>
      <material name="clearpath_red">
        <color rgba="0.9 0.0 0.0 1.0"/>
      </material>
    </visual>
    <collision>
      <origin rpy="0 0 0" xyz="0 0 0"/>
      <geometry>
        <mesh filename="package://clearpath_platform_description/meshes/w200/chassis-collision.stl"/>
      </geometry>
    </collision>
  </link>
  <link name="left_diff_unit_link">
    <inertial>
      <origin rpy="0 0 0" xyz="0 -0.05 0.197"/>
      <mass value="50"/>
      <inertia ixx="1.980416666666667" ixy="0" ixz="0" iyy="9.135416666666668" iyz="0" izz="9.135416666666668"/>
    </inertial>
    <visual>
      <origin rpy="0 0 1.5707963267948966" xyz="0 0 0"/>
      <geometry>
        <mesh filename="package://clearpath_platform_description/meshes/w200/fenders.stl"/>
      </geometry>
      <material name="warthog_yellow"/>
    </visual>
    <collision>
      <origin rpy="0 0 1.5707963267948966" xyz="0 0 0"/>
      <geometry>
        <mesh filename="package://clearpath_platform_description/meshes/w200/fenders.stl"/>
      </geometry>
    </collision>
    <visual>
      <origin rpy="0 0 1.5707963267948966" xyz="0 0 0"/>
      <geometry>
        <mesh filename="package://clearpath_platform_description/meshes/w200/rocker.stl"/>
      </geometry>
      <material name="clearpath_black"/>
    </visual>
  </link>
  <joint name="left_diff_unit_joint" type="fixed">
    <limit effort="100" lower="-0.4" upper="0.4" velocity="1"/>
    <parent link="chassis_link"/>
    <child link="left_diff_unit_link"/>
    <origin rpy="0 0 0" xyz="0.0 0.56821 0.0"/>
    <axis xyz="0 1 0"/>
    <dynamics damping="100" friction="0.5"/>
  </joint>
  <link name="left_diff_unit_headlight_link">
    <visual>
      <origin rpy="0 0 0" xyz="0 -0.0244 0"/>
      <geometry>
        <mesh filename="package://clearpath_platform_description/meshes/w200/light.stl"/>
      </geometry>
      <material name="clearpath_white"/>
    </visual>
  </link>
  <joint name="left_diff_unit_headlight_joint" type="fixed">
    <parent link="left_diff_unit_link"/>
    <child link="left_diff_unit_headlight_link"/>
    <origin rpy="0 0 0" xyz="0 0 0"/>
  </joint>
  <gazebo reference="left_diff_unit_headlight_link">
    <visual>
      <material>
        <ambient>0.9 0.9 0.9 1</ambient>
        <diffuse>0.9 0.9 0.9 1</diffuse>
        <specular>0.9 0.9 0.9 1</specular>
        <emissive>0.9 0.9 0.9 1</emissive>
      </material>
    </visual>
  </gazebo>
  <link name="left_diff_unit_taillight_link">
    <visual>
      <origin rpy="0 0 3.141592653589793" xyz="0 -0.0244 0"/>
      <geometry>
        <mesh filename="package://clearpath_platform_description/meshes/w200/light.stl"/>
      </geometry>
      <material name="clearpath_red"/>
    </visual>
  </link>
  <joint name="left_diff_unit_taillight_joint" type="fixed">
    <parent link="left_diff_unit_link"/>
    <child link="left_diff_unit_taillight_link"/>
    <origin rpy="0 0 0" xyz="0 0 0"/>
  </joint>
  <gazebo reference="left_diff_unit_taillight_link">
    <visual>
      <material>
        <ambient>0.9 0 0 1</ambient>
        <diffuse>0.9 0 0 1</diffuse>
        <specular>0.9 0 0 1</specular>
        <emissive>0.9 0 0 1</emissive>
      </material>
    </visual>
  </gazebo>
  <gazebo reference="left_diff_unit_link">
    <selfCollide>false</selfCollide>
    <visual>
      <material>
        <specular>0.1 0.1 0.1 1</specular>
        <emissive>0 0 0 0</emissive>
      </material>
    </visual>
  </gazebo>
  <link name="right_diff_unit_link">
    <inertial>
      <origin rpy="0 0 0" xyz="0 0.05 0.197"/>
      <mass value="50"/>
      <inertia ixx="1.980416666666667" ixy="0" ixz="0" iyy="9.135416666666668" iyz="0" izz="9.135416666666668"/>
    </inertial>
    <visual>
      <origin rpy="0 0 -1.5707963267948966" xyz="0 0 0"/>
      <geometry>
        <mesh filename="package://clearpath_platform_description/meshes/w200/fenders.stl"/>
      </geometry>
      <material name="warthog_yellow"/>
    </visual>
    <collision>
      <origin rpy="0 0 -1.5707963267948966" xyz="0 0 0"/>
      <geometry>
        <mesh filename="package://clearpath_platform_description/meshes/w200/fenders.stl"/>
      </geometry>
    </collision>
    <visual>
      <origin rpy="0 0 -1.5707963267948966" xyz="0 0 0"/>
      <geometry>
        <mesh filename="package://clearpath_platform_description/meshes/w200/rocker.stl"/>
      </geometry>
      <material name="clearpath_black"/>
    </visual>
  </link>
  <joint name="right_diff_unit_joint" type="fixed">
    <limit effort="100" lower="-0.4" upper="0.4" velocity="1"/>
    <parent link="chassis_link"/>
    <child link="right_diff_unit_link"/>
    <origin rpy="0 0 0" xyz="0.0 -0.56821 0.0"/>
    <axis xyz="0 1 0"/>
    <dynamics damping="100" friction="0.5"/>
  </joint>
  <link name="right_diff_unit_headlight_link">
    <visual>
      <origin rpy="0 0 0" xyz="0 0.0244 0"/>
      <geometry>
        <mesh filename="package://clearpath_platform_description/meshes/w200/light.stl"/>
      </geometry>
      <material name="clearpath_white"/>
    </visual>
  </link>
  <joint name="right_diff_unit_headlight_joint" type="fixed">
    <parent link="right_diff_unit_link"/>
    <child link="right_diff_unit_headlight_link"/>
    <origin rpy="0 0 0" xyz="0 0 0"/>
  </joint>
  <gazebo reference="right_diff_unit_headlight_link">
    <visual>
      <material>
        <ambient>0.9 0.9 0.9 1</ambient>
        <diffuse>0.9 0.9 0.9 1</diffuse>
        <specular>0.9 0.9 0.9 1</specular>
        <emissive>0.9 0.9 0.9 1</emissive>
      </material>
    </visual>
  </gazebo>
  <link name="right_diff_unit_taillight_link">
    <visual>
      <origin rpy="0 0 -3.141592653589793" xyz="0 0.0244 0"/>
      <geometry>
        <mesh filename="package://clearpath_platform_description/meshes/w200/light.stl"/>
      </geometry>
      <material name="clearpath_red"/>
    </visual>
  </link>
  <joint name="right_diff_unit_taillight_joint" type="fixed">
    <parent link="right_diff_unit_link"/>
    <child link="right_diff_unit_taillight_link"/>
    <origin rpy="0 0 0" xyz="0 0 0"/>
  </joint>
  <gazebo reference="right_diff_unit_taillight_link">
    <visual>
      <material>
        <ambient>0.9 0 0 1</ambient>
        <diffuse>0.9 0 0 1</diffuse>
        <specular>0.9 0 0 1</specular>
        <emissive>0.9 0 0 1</emissive>
      </material>
    </visual>
  </gazebo>
  <gazebo reference="right_diff_unit_link">
    <selfCollide>false</selfCollide>
    <visual>
      <material>
        <specular>0.1 0.1 0.1 1</specular>
        <emissive>0 0 0 0</emissive>
      </material>
    </visual>
  </gazebo>
  <link name="diff_link">
    <visual>
      <origin rpy="0 0 0" xyz="0 0 0"/>
      <geometry>
        <mesh filename="package://clearpath_platform_description/meshes/w200/diff-link.stl"/>
      </geometry>
      <material name="clearpath_light_grey"/>
    </visual>
    <visual>
      <origin rpy="0 0 0" xyz="0 0 0"/>
      <geometry>
        <mesh filename="package://clearpath_platform_description/meshes/w200/susp-link.stl"/>
      </geometry>
      <material name="clearpath_light_grey"/>
    </visual>
    <visual>
      <origin rpy="0 0 0" xyz="0 0 0"/>
      <geometry>
        <mesh filename="package://clearpath_platform_description/meshes/w200/susp-link.stl"/>
      </geometry>
      <material name="clearpath_light_grey"/>
    </visual>
  </link>
  <joint name="diff_link_joint" type="fixed">
    <parent link="chassis_link"/>
    <child link="diff_link"/>
    <origin rpy="0 0 0" xyz="-0.5826 0 0.24979"/>
  </joint>
  <link name="front_left_wheel_link">
    <inertial>
      <origin rpy="0 0 0" xyz="0 0 0"/>
      <mass value="15"/>
      <inertia ixx="0.41562499999999997" ixy="0" ixz="0" iyy="0.6749999999999999" iyz="0" izz="0.41562499999999997"/>
    </inertial>
    <visual>
      <origin rpy="0 0 1.5707963267948966" xyz="0 0 0"/>
      <geometry>
        <mesh filename="package://clearpath_platform_description/meshes/w200/wheel.stl"/>
      </geometry>
      <material name="clearpath_dark_grey"/>
    </visual>
    <collision>
      <origin rpy="1.5707963267948966 0 0" xyz="0 0 0"/>
      <geometry>
        <cylinder length="0.25" radius="0.3"/>
      </geometry>
    </collision>
  </link>
  <joint name="front_left_wheel_joint" type="continuous">
    <parent link="left_diff_unit_link"/>
    <child link="front_left_wheel_link"/>
    <origin rpy="0 0 0" xyz="0.457367 0.0 -0.012977"/>
    <axis xyz="0 1 0"/>
  </joint>
  <gazebo reference="front_left_wheel_link">
    <selfCollide>false</selfCollide>
    <mu1>0.5</mu1>
    <mu2>0.5</mu2>
    <fdir1 value="1 0 0"/>
    <material>Gazebo/DarkGrey</material>
  </gazebo>
  <link name="front_right_wheel_link">
    <inertial>
      <origin rpy="0 0 0" xyz="0 0 0"/>
      <mass value="15"/>
      <inertia ixx="0.41562499999999997" ixy="0" ixz="0" iyy="0.6749999999999999" iyz="0" izz="0.41562499999999997"/>
    </inertial>
    <visual>
      <origin rpy="0 0 1.5707963267948966" xyz="0 0 0"/>
      <geometry>
        <mesh filename="package://clearpath_platform_description/meshes/w200/wheel.stl"/>
      </geometry>
      <material name="clearpath_dark_grey"/>
    </visual>
    <collision>
      <origin rpy="1.5707963267948966 0 0" xyz="0 0 0"/>
      <geometry>
        <cylinder length="0.25" radius="0.3"/>
      </geometry>
    </collision>
  </link>
  <joint name="front_right_wheel_joint" type="continuous">
    <parent link="right_diff_unit_link"/>
    <child link="front_right_wheel_link"/>
    <origin rpy="0 0 0" xyz="0.457367 -0.0 -0.012977"/>
    <axis xyz="0 1 0"/>
  </joint>
  <gazebo reference="front_right_wheel_link">
    <selfCollide>false</selfCollide>
    <mu1>0.5</mu1>
    <mu2>0.5</mu2>
    <fdir1 value="1 0 0"/>
    <material>Gazebo/DarkGrey</material>
  </gazebo>
  <link name="rear_left_wheel_link">
    <inertial>
      <origin rpy="0 0 0" xyz="0 0 0"/>
      <mass value="15"/>
      <inertia ixx="0.41562499999999997" ixy="0" ixz="0" iyy="0.6749999999999999" iyz="0" izz="0.41562499999999997"/>
    </inertial>
    <visual>
      <origin rpy="0 0 1.5707963267948966" xyz="0 0 0"/>
      <geometry>
        <mesh filename="package://clearpath_platform_description/meshes/w200/wheel.stl"/>
      </geometry>
      <material name="clearpath_dark_grey"/>
    </visual>
    <collision>
      <origin rpy="1.5707963267948966 0 0" xyz="0 0 0"/>
      <geometry>
        <cylinder length="0.25" radius="0.3"/>
      </geometry>
    </collision>
  </link>
  <joint name="rear_left_wheel_joint" type="continuous">
    <parent link="left_diff_unit_link"/>
    <child link="rear_left_wheel_link"/>
    <origin rpy="0 0 0" xyz="-0.457367 0.0 -0.012977"/>
    <axis xyz="0 1 0"/>
  </joint>
  <gazebo reference="rear_left_wheel_link">
    <selfCollide>false</selfCollide>
    <mu1>0.5</mu1>
    <mu2>0.5</mu2>
    <fdir1 value="1 0 0"/>
    <material>Gazebo/DarkGrey</material>
  </gazebo>
  <link name="rear_right_wheel_link">
    <inertial>
      <origin rpy="0 0 0" xyz="0 0 0"/>
      <mass value="15"/>
      <inertia ixx="0.41562499999999997" ixy="0" ixz="0" iyy="0.6749999999999999" iyz="0" izz="0.41562499999999997"/>
    </inertial>
    <visual>
      <origin rpy="0 0 1.5707963267948966" xyz="0 0 0"/>
      <geometry>
        <mesh filename="package://clearpath_platform_description/meshes/w200/wheel.stl"/>
      </geometry>
      <material name="clearpath_dark_grey"/>
    </visual>
    <collision>
      <origin rpy="1.5707963267948966 0 0" xyz="0 0 0"/>
      <geometry>
        <cylinder length="0.25" radius="0.3"/>
      </geometry>
    </collision>
  </link>
  <joint name="rear_right_wheel_joint" type="continuous">
    <parent link="right_diff_unit_link"/>
    <child link="rear_right_wheel_link"/>
    <origin rpy="0 0 0" xyz="-0.457367 -0.0 -0.012977"/>
    <axis xyz="0 1 0"/>
  </joint>
  <gazebo reference="rear_right_wheel_link">
    <selfCollide>false</selfCollide>
    <mu1>0.5</mu1>
    <mu2>0.5</mu2>
    <fdir1 value="1 0 0"/>
    <material>Gazebo/DarkGrey</material>
  </gazebo>
  <!-- Virtual Mounting Point -->
  <link name="default_mount"/>
  <joint name="default_mount_joint" type="fixed">
    <origin rpy="0 0 0" xyz="0 0 0.27218"/>
    <parent link="chassis_link"/>
    <child link="default_mount"/>
  </joint>
  <!-- Internal IMU -->
  <link name="imu_0_link">
    <inertial>
      <mass value="0.001"/>
      <origin rpy="0 0 0" xyz="0 0 0"/>
      <inertia ixx="1e-09" ixy="0.0" ixz="0.0" iyy="1e-09" iyz="0.0" izz="1e-09"/>
    </inertial>
  </link>
  <joint name="imu_joint" type="fixed">
    <parent link="chassis_link"/>
    <child link="imu_0_link"/>
  </joint>
  <gazebo reference="imu_0_link">
    <sensor name="imu_0" type="imu">
      <always_on>true</always_on>
      <update_rate>50</update_rate>
      <visualize>true</visualize>
      <ignition_frame_id>imu_0_link</ignition_frame_id>
    </sensor>
  </gazebo>
  <gazebo>
    <plugin filename="libign_ros2_control-system.so" name="ign_ros2_control::IgnitionROS2ControlPlugin">
      <parameters>/home/duser/clearpath/platform/config/control.yaml</parameters>
      <ros>
        <remapping>~/odom:=platform/odom</remapping>
        <remapping>~/cmd_vel_unstamped:=platform/cmd_vel_unstamped</remapping>
        <remapping>/tf:=tf</remapping>
        <remapping>/tf_static:=tf_static</remapping>
        <remapping>/diagnostics:=diagnostics</remapping>
        <remapping>joint_states:=platform/joint_states</remapping>
        <namespace>w200_0000</namespace>
      </ros>
    </plugin>
  </gazebo>
  <gazebo>
    <plugin filename="libignition-gazebo-pose-publisher-system.so" name="ignition::gazebo::systems::PosePublisher">
      <publish_link_pose>true</publish_link_pose>
      <publish_nested_model_pose>true</publish_nested_model_pose>
      <use_pose_vector_msg>true</use_pose_vector_msg>
      <update_frequency>50</update_frequency>
    </plugin>
  </gazebo>
  <!-- ROS2 controls -->
  <ros2_control name="w200_hardware" type="system">
    <hardware>
      <plugin>ign_ros2_control/IgnitionSystem</plugin>
    </hardware>
    <joint name="front_left_wheel_joint">
      <command_interface name="velocity">
        <param name="min">-25</param>
        <param name="max">25</param>
      </command_interface>
      <state_interface name="position"/>
      <state_interface name="velocity"/>
    </joint>
    <joint name="rear_left_wheel_joint">
      <command_interface name="velocity">
        <param name="min">-25</param>
        <param name="max">25</param>
      </command_interface>
      <state_interface name="position"/>
      <state_interface name="velocity"/>
    </joint>
    <joint name="front_right_wheel_joint">
      <command_interface name="velocity">
        <param name="min">-25</param>
        <param name="max">25</param>
      </command_interface>
      <state_interface name="position"/>
      <state_interface name="velocity"/>
    </joint>
    <joint name="rear_right_wheel_joint">
      <command_interface name="velocity">
        <param name="min">-25</param>
        <param name="max">25</param>
      </command_interface>
      <state_interface name="position"/>
      <state_interface name="velocity"/>
    </joint>
  </ros2_control>
  <gazebo>
    <plugin filename="libignition-gazebo-wheel-slip-system.so" name="ignition::gazebo::systems::WheelSlip">
      <wheel link_name="front_left_wheel_link">
        <slip_compliance_lateral>1.0</slip_compliance_lateral>
        <slip_compliance_longitudinal>1.0</slip_compliance_longitudinal>
        <wheel_normal_force>686</wheel_normal_force>
        <wheel_radius>0.3</wheel_radius>
      </wheel>
      <wheel link_name="front_right_wheel_link">
        <slip_compliance_lateral>1.0</slip_compliance_lateral>
        <slip_compliance_longitudinal>1.0</slip_compliance_longitudinal>
        <wheel_normal_force>686</wheel_normal_force>
        <wheel_radius>0.3</wheel_radius>
      </wheel>
      <wheel link_name="rear_left_wheel_link">
        <slip_compliance_lateral>1.0</slip_compliance_lateral>
        <slip_compliance_longitudinal>1.0</slip_compliance_longitudinal>
        <wheel_normal_force>686</wheel_normal_force>
        <wheel_radius>0.3</wheel_radius>
      </wheel>
      <wheel link_name="rear_right_wheel_link">
        <slip_compliance_lateral>1.0</slip_compliance_lateral>
        <slip_compliance_longitudinal>1.0</slip_compliance_longitudinal>
        <wheel_normal_force>686</wheel_normal_force>
        <wheel_radius>0.3</wheel_radius>
      </wheel>
    </plugin>
  </gazebo>
  <!-- Attachments -->
  <!-- Links -->
  <!-- Mounts -->
  <!-- Sensors -->
  <!-- Extras -->
</robot>

